<?xml version="1.0" encoding="UTF-8"?>
<robot name="scene">
  <joint name="joint_1" type="revolute">
    <origin xyz="0. 0. 0.33" rpy="0. -1.5707964 0. "/>
    <parent link="scene"/>
    <child link="scene_kuka_arm_link_1_kuka_arm_link_1"/>
    <axis xyz="1. 0. 0."/>
    <limit lower="-3.2288596" upper="3.2288596" effort="0." velocity="17453.2925199"/>
  </joint>
  <joint name="joint_2" type="revolute">
    <origin xyz="0.42 0. -0.35" rpy="1.5707964 0. 1.5707964"/>
    <parent link="scene_kuka_arm_link_1_kuka_arm_link_1"/>
    <child link="kuka_arm_link_2"/>
    <axis xyz="1. 0. 0."/>
    <limit lower="-0.785398" upper="1.48353" effort="0." velocity="17453.2925199"/>
  </joint>
  <joint name="joint_3" type="revolute">
    <origin xyz="0. 0. 1.25" rpy="0. 0. 0."/>
    <parent link="kuka_arm_link_2"/>
    <child link="kuka_arm_link_3"/>
    <axis xyz="1. 0. 0."/>
    <limit lower="-3.6651898" upper="1.1344599" effort="0." velocity="17453.2925199"/>
  </joint>
  <joint name="joint_4" type="revolute">
    <origin xyz="0. -0.9599999 -0.054 " rpy="0. 0. -1.5707964"/>
    <parent link="kuka_arm_link_3"/>
    <child link="kuka_arm_link_4"/>
    <axis xyz="1. 0. 0."/>
    <limit lower="-6.1086497" upper="6.1086497" effort="0." velocity="17453.2925199"/>
  </joint>
  <joint name="joint_5" type="revolute">
    <origin xyz="0.54 0. 0. " rpy="0. 0. 1.5707964"/>
    <parent link="kuka_arm_link_4"/>
    <child link="kuka_arm_link_5"/>
    <axis xyz="1. 0. 0."/>
    <limit lower="-2.1816598" upper="2.1816598" effort="0." velocity="17453.2925199"/>
  </joint>
  <joint name="joint_6" type="revolute">
    <origin xyz="0. -0.1930001 0. " rpy="0. 0. -1.5707964"/>
    <parent link="kuka_arm_link_5"/>
    <child link="kuka_arm_link_6"/>
    <axis xyz="1. 0. 0."/>
    <limit lower="-6.1086497" upper="6.1086497" effort="0." velocity="17453.2925199"/>
  </joint>
  <joint name="left_gripper_finger_joint" type="prismatic">
    <origin xyz="0.26 0.0725 0. " rpy="3.1415927 0. -1.5707964"/>
    <parent link="kuka_arm_link_6"/>
    <child link="left_gripper_finger_link"/>
    <axis xyz="1. 0. 0."/>
    <limit lower="-0.01" upper="0.06" effort="0." velocity="1000000."/>
  </joint>
  <joint name="right_gripper_finger_joint" type="prismatic">
    <origin xyz="0.26 -0.0725 0. " rpy="0. 0. 1.5707964"/>
    <parent link="kuka_arm_link_6"/>
    <child link="right_gripper_finger_link"/>
    <axis xyz="1. 0. 0."/>
    <limit lower="-0.01" upper="0.06" effort="0." velocity="1000000."/>
  </joint>

    <joint name="gripper_joint" type="fixed">
        <parent link="kuka_arm_link_6"/>
        <child link="gripper_link"/>
        <origin rpy="1.57 0 0" xyz="0.11 0 0"/>
        <axis xyz="0 1 0"/>
    </joint>
    <link name="gripper_link">
        <inertial>
            <origin rpy="0 0 0" xyz="0 0 0"/>
            <mass value="0.3"/>
            <inertia ixx="0.0001" ixy="0" ixz="0" iyy="0.0002" iyz="0" izz="0.0001"/>
        </inertial>
        <visual>
            <origin rpy="0 0 0" xyz="0 0 0"/>
            <geometry>
                <mesh filename="meshes/kuka_arm_link_6_visuals_gripper_base_mesh.obj"/>
            </geometry>
        </visual>
        <collision>
            <origin rpy="0 0 0" xyz="0 0 0"/>
            <geometry>
                <mesh filename="meshes/kuka_arm_link_6_visuals_gripper_base_mesh.obj"/>
            </geometry>
        </collision>
    </link>

  <link name="kuka_arm_link_2">
    <visual>
      <origin xyz="0. 0. 0." rpy="-0.0000091 0. -1.5707964"/>
      <geometry>
        <mesh filename="meshes/kuka_arm_link_2_visuals_mesh.obj" scale="1. 1. 1."/>
      </geometry>
    </visual>
    <visual>
      <origin xyz="0. 0. 0." rpy="-0.0000091 0. -1.5707964"/>
      <geometry>
        <mesh filename="meshes/kuka_arm_link_2_collisions_mesh.obj" scale="1. 1. 1."/>
      </geometry>
    </visual>
  </link>
  <link name="kuka_arm_link_3">
    <visual>
      <origin xyz="-0.184 0. 0. " rpy="-0.0000091 0. -1.5707964"/>
      <geometry>
        <mesh filename="meshes/kuka_arm_link_3_visuals_mesh.obj" scale="1. 1. 1."/>
      </geometry>
    </visual>
    <visual>
      <origin xyz="-0.184 0. 0. " rpy="-0.0000091 0. -1.5707964"/>
      <geometry>
        <mesh filename="meshes/kuka_arm_link_3_collisions_mesh.obj" scale="1. 1. 1."/>
      </geometry>
    </visual>
  </link>
  <link name="kuka_arm_link_4">
    <visual>
      <origin xyz="0. 0. 0." rpy="-0.0000091 0. 0. "/>
      <geometry>
        <mesh filename="meshes/kuka_arm_link_4_visuals_mesh.obj" scale="1. 1. 1."/>
      </geometry>
    </visual>
    <visual>
      <origin xyz="0. 0. 0." rpy="-0.0000091 0. 0. "/>
      <geometry>
        <mesh filename="meshes/kuka_arm_link_4_collisions_mesh.obj" scale="1. 1. 1."/>
      </geometry>
    </visual>
  </link>
  <link name="kuka_arm_link_5">
    <visual>
      <origin xyz="0. 0.0000001 0. " rpy="-0.0000091 0. -1.5707964"/>
      <geometry>
        <mesh filename="meshes/kuka_arm_link_5_visuals_mesh.obj" scale="1. 1. 1."/>
      </geometry>
    </visual>
    <visual>
      <origin xyz="0. 0.0000001 0. " rpy="-0.0000091 0. -1.5707964"/>
      <geometry>
        <mesh filename="meshes/kuka_arm_link_5_collisions_mesh.obj" scale="1. 1. 1."/>
      </geometry>
    </visual>
  </link>
  <link name="kuka_arm_link_6">
    <visual>
      <origin xyz="0.0000001 0. 0. " rpy="1.570788 0. 0. "/>
      <geometry>
        <mesh filename="meshes/kuka_arm_link_6_visuals_mesh.obj" scale="1. 1. 1."/>
      </geometry>
    </visual>
    <visual>
      <origin xyz="0.0000001 0. 0. " rpy="1.570788 0. 0. "/>
      <geometry>
        <mesh filename="meshes/kuka_arm_link_6_collisions_mesh.obj" scale="1. 1. 1."/>
      </geometry>
    </visual>
  </link>
  <link name="left_gripper_finger_link">
    <visual>
      <origin xyz="0. 0. 0." rpy="-1.5708046 0. -1.5707964"/>
      <geometry>
        <mesh filename="meshes/left_gripper_finger_link_visuals_mesh.obj" scale="1. 1. 1."/>
      </geometry>
    </visual>
    <visual>
      <origin xyz="0. 0. 0." rpy="-1.5708046 0. -1.5707964"/>
      <geometry>
        <mesh filename="meshes/left_gripper_finger_link_collisions_mesh.obj" scale="1. 1. 1."/>
      </geometry>
    </visual>
  </link>
  <link name="right_gripper_finger_link">
    <visual>
      <origin xyz="0. 0. 0." rpy="1.570788 0. -1.5707964"/>
      <geometry>
        <mesh filename="meshes/right_gripper_finger_link_visuals_mesh.obj" scale="1. 1. 1."/>
      </geometry>
    </visual>
    <visual>
      <origin xyz="0. 0. 0." rpy="1.570788 0. -1.5707964"/>
      <geometry>
        <mesh filename="meshes/right_gripper_finger_link_collisions_mesh.obj" scale="1. 1. 1."/>
      </geometry>
    </visual>
  </link>
  <link name="scene">
    <visual>
      <origin xyz="0. 0. 0." rpy="-0.0000091 0. 0. "/>
      <geometry>
        <mesh filename="meshes/worldBody___visuals___mesh.obj" scale="1. 1. 1."/>
      </geometry>
    </visual>
    <visual>
      <origin xyz="0. 0. 0." rpy="-0.0000091 0. 0. "/>
      <geometry>
        <mesh filename="meshes/worldBody___collisions___mesh.obj" scale="1. 1. 1."/>
      </geometry>
    </visual>
    <visual>
      <origin xyz="0. 0. 0." rpy="0. 0. 0."/>
      <geometry>
        <mesh filename="meshes/worldBody_floor_visuals_floor_floor.obj" scale="1. 1. 1."/>
      </geometry>
    </visual>
    <visual>
      <origin xyz="3.2 0. 0. " rpy="0. 0. 1.57"/>
      <geometry>
        <box size="6. 0.05 6. "/>
      </geometry>
    </visual>
    <visual>
      <origin xyz="3.2 -1.8 1.5" rpy="0. 0. 1.57"/>
      <geometry>
        <cylinder radius="0.5" length="3."/>
      </geometry>
    </visual>
    <visual>
      <origin xyz="3.2 1.8 1.5" rpy="0. 0. 1.57"/>
      <geometry>
        <cylinder radius="0.5" length="3."/>
      </geometry>
    </visual>
    <visual>
      <origin xyz="3. 0.5 0.6" rpy="0. 0. 0."/>
      <geometry>
        <cylinder radius="0.024" length="1.2"/>
      </geometry>
    </visual>
    <visual>
      <origin xyz="3. -0.5 0.6" rpy="0. 0. 0."/>
      <geometry>
        <cylinder radius="0.024" length="1.2"/>
      </geometry>
    </visual>
    <visual>
      <origin xyz="2.4 0.5 0.6" rpy="0. 0. 0."/>
      <geometry>
        <cylinder radius="0.024" length="1.2"/>
      </geometry>
    </visual>
    <visual>
      <origin xyz="2.4 -0.5 0.6" rpy="0. 0. 0."/>
      <geometry>
        <cylinder radius="0.024" length="1.2"/>
      </geometry>
    </visual>
    <visual>
      <origin xyz="2.7 0.5 0.2" rpy="0. 1.57 0. "/>
      <geometry>
        <cylinder radius="0.024" length="0.6"/>
      </geometry>
    </visual>
    <visual>
      <origin xyz="2.7 -0.5 0.2" rpy="0. 1.57 0. "/>
      <geometry>
        <cylinder radius="0.024" length="0.6"/>
      </geometry>
    </visual>
    <visual>
      <origin xyz="2.4 0. 0.2" rpy="1.57 0. 0. "/>
      <geometry>
        <cylinder radius="0.024" length="1."/>
      </geometry>
    </visual>
    <visual>
      <origin xyz="3. 0. 0.2" rpy="1.57 0. 0. "/>
      <geometry>
        <cylinder radius="0.024" length="1."/>
      </geometry>
    </visual>
    <visual>
      <origin xyz="2.7 0.5 1.2" rpy="0. 1.57 0. "/>
      <geometry>
        <cylinder radius="0.024" length="0.6"/>
      </geometry>
    </visual>
    <visual>
      <origin xyz="2.7 -0.5 1.2" rpy="0. 1.57 0. "/>
      <geometry>
        <cylinder radius="0.024" length="0.6"/>
      </geometry>
    </visual>
    <visual>
      <origin xyz="2.4 0. 1.2" rpy="1.57 0. 0. "/>
      <geometry>
        <cylinder radius="0.024" length="1."/>
      </geometry>
    </visual>
    <visual>
      <origin xyz="3. 0. 1.2" rpy="1.57 0. 0. "/>
      <geometry>
        <cylinder radius="0.024" length="1."/>
      </geometry>
    </visual>
    <visual>
      <origin xyz="2.4 0. 0.7" rpy="0.785 0. 0. "/>
      <geometry>
        <cylinder radius="0.024" length="1.414"/>
      </geometry>
    </visual>
    <visual>
      <origin xyz="3. 0. 0.7" rpy="-0.785 0. 0. "/>
      <geometry>
        <cylinder radius="0.024" length="1.414"/>
      </geometry>
    </visual>
    <visual>
      <origin xyz="3. 0.5 1.7" rpy="0. 0. 0."/>
      <geometry>
        <cylinder radius="0.024" length="1."/>
      </geometry>
    </visual>
    <visual>
      <origin xyz="3. -0.5 1.7" rpy="0. 0. 0."/>
      <geometry>
        <cylinder radius="0.024" length="1."/>
      </geometry>
    </visual>
    <visual>
      <origin xyz="2.4 0.5 1.7" rpy="0. 0. 0."/>
      <geometry>
        <cylinder radius="0.024" length="1."/>
      </geometry>
    </visual>
    <visual>
      <origin xyz="2.4 -0.5 1.7" rpy="0. 0. 0."/>
      <geometry>
        <cylinder radius="0.024" length="1."/>
      </geometry>
    </visual>
    <visual>
      <origin xyz="2.7 0.5 2.2" rpy="0. 1.57 0. "/>
      <geometry>
        <cylinder radius="0.024" length="0.6"/>
      </geometry>
    </visual>
    <visual>
      <origin xyz="2.7 -0.5 2.2" rpy="0. 1.57 0. "/>
      <geometry>
        <cylinder radius="0.024" length="0.6"/>
      </geometry>
    </visual>
    <visual>
      <origin xyz="2.4 0. 2.2" rpy="1.57 0. 0. "/>
      <geometry>
        <cylinder radius="0.024" length="1."/>
      </geometry>
    </visual>
    <visual>
      <origin xyz="3. 0. 2.2" rpy="1.57 0. 0. "/>
      <geometry>
        <cylinder radius="0.024" length="1."/>
      </geometry>
    </visual>
    <visual>
      <origin xyz="2.4 0. 1.7" rpy="0.785 0. 0. "/>
      <geometry>
        <cylinder radius="0.024" length="1.414"/>
      </geometry>
    </visual>
    <visual>
      <origin xyz="3. 0. 1.7" rpy="-0.785 0. 0. "/>
      <geometry>
        <cylinder radius="0.024" length="1.414"/>
      </geometry>
    </visual>
    <visual>
      <origin xyz="3. 1.1 1.7" rpy="0. 0. 0."/>
      <geometry>
        <cylinder radius="0.024" length="1."/>
      </geometry>
    </visual>
    <visual>
      <origin xyz="2.4 1.1 1.7" rpy="0. 0. 0."/>
      <geometry>
        <cylinder radius="0.024" length="1."/>
      </geometry>
    </visual>
    <visual>
      <origin xyz="3. 1.1 0.6" rpy="0. 0. 0."/>
      <geometry>
        <cylinder radius="0.024" length="1.2"/>
      </geometry>
    </visual>
    <visual>
      <origin xyz="2.4 1.1 0.6" rpy="0. 0. 0."/>
      <geometry>
        <cylinder radius="0.024" length="1.2"/>
      </geometry>
    </visual>
    <visual>
      <origin xyz="3. -1.1 1.7" rpy="0. 0. 0."/>
      <geometry>
        <cylinder radius="0.024" length="1."/>
      </geometry>
    </visual>
    <visual>
      <origin xyz="2.4 -1.1 1.7" rpy="0. 0. 0."/>
      <geometry>
        <cylinder radius="0.024" length="1."/>
      </geometry>
    </visual>
    <visual>
      <origin xyz="3. -1.1 0.6" rpy="0. 0. 0."/>
      <geometry>
        <cylinder radius="0.024" length="1.2"/>
      </geometry>
    </visual>
    <visual>
      <origin xyz="2.4 -1.1 0.6" rpy="0. 0. 0."/>
      <geometry>
        <cylinder radius="0.024" length="1.2"/>
      </geometry>
    </visual>
    <visual>
      <origin xyz="2.7 1.1 0.2" rpy="0. 1.57 0. "/>
      <geometry>
        <cylinder radius="0.024" length="0.6"/>
      </geometry>
    </visual>
    <visual>
      <origin xyz="2.7 1.1 1.2" rpy="0. 1.57 0. "/>
      <geometry>
        <cylinder radius="0.024" length="0.6"/>
      </geometry>
    </visual>
    <visual>
      <origin xyz="2.7 1.1 2.2" rpy="0. 1.57 0. "/>
      <geometry>
        <cylinder radius="0.024" length="0.6"/>
      </geometry>
    </visual>
    <visual>
      <origin xyz="2.7 -1.1 0.2" rpy="0. 1.57 0. "/>
      <geometry>
        <cylinder radius="0.024" length="0.6"/>
      </geometry>
    </visual>
    <visual>
      <origin xyz="2.7 -1.1 1.2" rpy="0. 1.57 0. "/>
      <geometry>
        <cylinder radius="0.024" length="0.6"/>
      </geometry>
    </visual>
    <visual>
      <origin xyz="2.7 -1.1 2.2" rpy="0. 1.57 0. "/>
      <geometry>
        <cylinder radius="0.024" length="0.6"/>
      </geometry>
    </visual>
    <visual>
      <origin xyz="2.4 -0.8 0.2" rpy="1.57 0. 0. "/>
      <geometry>
        <cylinder radius="0.024" length="0.6"/>
      </geometry>
    </visual>
    <visual>
      <origin xyz="2.4 -0.8 1.2" rpy="1.57 0. 0. "/>
      <geometry>
        <cylinder radius="0.024" length="0.6"/>
      </geometry>
    </visual>
    <visual>
      <origin xyz="2.4 -0.8 2.2" rpy="1.57 0. 0. "/>
      <geometry>
        <cylinder radius="0.024" length="0.6"/>
      </geometry>
    </visual>
    <visual>
      <origin xyz="3. -0.8 0.2" rpy="1.57 0. 0. "/>
      <geometry>
        <cylinder radius="0.024" length="0.6"/>
      </geometry>
    </visual>
    <visual>
      <origin xyz="3. -0.8 1.2" rpy="1.57 0. 0. "/>
      <geometry>
        <cylinder radius="0.024" length="0.6"/>
      </geometry>
    </visual>
    <visual>
      <origin xyz="3. -0.8 2.2" rpy="1.57 0. 0. "/>
      <geometry>
        <cylinder radius="0.024" length="0.6"/>
      </geometry>
    </visual>
    <visual>
      <origin xyz="2.4 0.8 0.2" rpy="1.57 0. 0. "/>
      <geometry>
        <cylinder radius="0.024" length="0.6"/>
      </geometry>
    </visual>
    <visual>
      <origin xyz="2.4 0.8 1.2" rpy="1.57 0. 0. "/>
      <geometry>
        <cylinder radius="0.024" length="0.6"/>
      </geometry>
    </visual>
    <visual>
      <origin xyz="2.4 0.8 2.2" rpy="1.57 0. 0. "/>
      <geometry>
        <cylinder radius="0.024" length="0.6"/>
      </geometry>
    </visual>
    <visual>
      <origin xyz="3. 0.8 0.2" rpy="1.57 0. 0. "/>
      <geometry>
        <cylinder radius="0.024" length="0.6"/>
      </geometry>
    </visual>
    <visual>
      <origin xyz="3. 0.8 1.2" rpy="1.57 0. 0. "/>
      <geometry>
        <cylinder radius="0.024" length="0.6"/>
      </geometry>
    </visual>
    <visual>
      <origin xyz="3. 0.8 2.2" rpy="1.57 0. 0. "/>
      <geometry>
        <cylinder radius="0.024" length="0.6"/>
      </geometry>
    </visual>
    <visual>
      <origin xyz="1.8 1.1 1.7" rpy="0. 0. 0."/>
      <geometry>
        <cylinder radius="0.024" length="1."/>
      </geometry>
    </visual>
    <visual>
      <origin xyz="1.8 1.1 0.6" rpy="0. 0. 0."/>
      <geometry>
        <cylinder radius="0.024" length="1.2"/>
      </geometry>
    </visual>
    <visual>
      <origin xyz="1.8 0.5 1.7" rpy="0. 0. 0."/>
      <geometry>
        <cylinder radius="0.024" length="1."/>
      </geometry>
    </visual>
    <visual>
      <origin xyz="1.8 0.5 0.6" rpy="0. 0. 0."/>
      <geometry>
        <cylinder radius="0.024" length="1.2"/>
      </geometry>
    </visual>
    <visual>
      <origin xyz="1.8 -1.1 1.7" rpy="0. 0. 0."/>
      <geometry>
        <cylinder radius="0.024" length="1."/>
      </geometry>
    </visual>
    <visual>
      <origin xyz="1.8 -1.1 0.6" rpy="0. 0. 0."/>
      <geometry>
        <cylinder radius="0.024" length="1.2"/>
      </geometry>
    </visual>
    <visual>
      <origin xyz="1.8 -0.5 1.7" rpy="0. 0. 0."/>
      <geometry>
        <cylinder radius="0.024" length="1."/>
      </geometry>
    </visual>
    <visual>
      <origin xyz="1.8 -0.5 0.6" rpy="0. 0. 0."/>
      <geometry>
        <cylinder radius="0.024" length="1.2"/>
      </geometry>
    </visual>
    <visual>
      <origin xyz="2.1 1.1 0.2" rpy="0. 1.57 0. "/>
      <geometry>
        <cylinder radius="0.024" length="0.6"/>
      </geometry>
    </visual>
    <visual>
      <origin xyz="2.1 1.1 1.2" rpy="0. 1.57 0. "/>
      <geometry>
        <cylinder radius="0.024" length="0.6"/>
      </geometry>
    </visual>
    <visual>
      <origin xyz="2.1 1.1 2.2" rpy="0. 1.57 0. "/>
      <geometry>
        <cylinder radius="0.024" length="0.6"/>
      </geometry>
    </visual>
    <visual>
      <origin xyz="2.1 -1.1 0.2" rpy="0. 1.57 0. "/>
      <geometry>
        <cylinder radius="0.024" length="0.6"/>
      </geometry>
    </visual>
    <visual>
      <origin xyz="2.1 -1.1 1.2" rpy="0. 1.57 0. "/>
      <geometry>
        <cylinder radius="0.024" length="0.6"/>
      </geometry>
    </visual>
    <visual>
      <origin xyz="2.1 -1.1 2.2" rpy="0. 1.57 0. "/>
      <geometry>
        <cylinder radius="0.024" length="0.6"/>
      </geometry>
    </visual>
    <visual>
      <origin xyz="2.1 0.5 0.2" rpy="0. 1.57 0. "/>
      <geometry>
        <cylinder radius="0.024" length="0.6"/>
      </geometry>
    </visual>
    <visual>
      <origin xyz="2.1 0.5 1.2" rpy="0. 1.57 0. "/>
      <geometry>
        <cylinder radius="0.024" length="0.6"/>
      </geometry>
    </visual>
    <visual>
      <origin xyz="2.1 0.5 2.2" rpy="0. 1.57 0. "/>
      <geometry>
        <cylinder radius="0.024" length="0.6"/>
      </geometry>
    </visual>
    <visual>
      <origin xyz="2.1 -0.5 0.2" rpy="0. 1.57 0. "/>
      <geometry>
        <cylinder radius="0.024" length="0.6"/>
      </geometry>
    </visual>
    <visual>
      <origin xyz="2.1 -0.5 1.2" rpy="0. 1.57 0. "/>
      <geometry>
        <cylinder radius="0.024" length="0.6"/>
      </geometry>
    </visual>
    <visual>
      <origin xyz="2.1 -0.5 2.2" rpy="0. 1.57 0. "/>
      <geometry>
        <cylinder radius="0.024" length="0.6"/>
      </geometry>
    </visual>
    <visual>
      <origin xyz="1.8 -0.8 0.2" rpy="1.57 0. 0. "/>
      <geometry>
        <cylinder radius="0.024" length="0.6"/>
      </geometry>
    </visual>
    <visual>
      <origin xyz="1.8 -0.8 1.2" rpy="1.57 0. 0. "/>
      <geometry>
        <cylinder radius="0.024" length="0.6"/>
      </geometry>
    </visual>
    <visual>
      <origin xyz="1.8 -0.8 2.2" rpy="1.57 0. 0. "/>
      <geometry>
        <cylinder radius="0.024" length="0.6"/>
      </geometry>
    </visual>
    <visual>
      <origin xyz="1.8 0.8 0.2" rpy="1.57 0. 0. "/>
      <geometry>
        <cylinder radius="0.024" length="0.6"/>
      </geometry>
    </visual>
    <visual>
      <origin xyz="1.8 0.8 1.2" rpy="1.57 0. 0. "/>
      <geometry>
        <cylinder radius="0.024" length="0.6"/>
      </geometry>
    </visual>
    <visual>
      <origin xyz="1.8 0.8 2.2" rpy="1.57 0. 0. "/>
      <geometry>
        <cylinder radius="0.024" length="0.6"/>
      </geometry>
    </visual>
    <visual>
      <origin xyz="1.8 2.1 1.7" rpy="0. 0. 0."/>
      <geometry>
        <cylinder radius="0.024" length="1."/>
      </geometry>
    </visual>
    <visual>
      <origin xyz="1.8 2.1 0.6" rpy="0. 0. 0."/>
      <geometry>
        <cylinder radius="0.024" length="1.2"/>
      </geometry>
    </visual>
    <visual>
      <origin xyz="1.8 -2.1 1.7" rpy="0. 0. 0."/>
      <geometry>
        <cylinder radius="0.024" length="1."/>
      </geometry>
    </visual>
    <visual>
      <origin xyz="1.8 -2.1 0.6" rpy="0. 0. 0."/>
      <geometry>
        <cylinder radius="0.024" length="1.2"/>
      </geometry>
    </visual>
    <visual>
      <origin xyz="2.4 2.1 1.7" rpy="0. 0. 0."/>
      <geometry>
        <cylinder radius="0.024" length="1."/>
      </geometry>
    </visual>
    <visual>
      <origin xyz="2.4 2.1 0.6" rpy="0. 0. 0."/>
      <geometry>
        <cylinder radius="0.024" length="1.2"/>
      </geometry>
    </visual>
    <visual>
      <origin xyz="2.4 -2.1 1.7" rpy="0. 0. 0."/>
      <geometry>
        <cylinder radius="0.024" length="1."/>
      </geometry>
    </visual>
    <visual>
      <origin xyz="2.4 -2.1 0.6" rpy="0. 0. 0."/>
      <geometry>
        <cylinder radius="0.024" length="1.2"/>
      </geometry>
    </visual>
    <visual>
      <origin xyz="2.1 2.1 0.2" rpy="0. 1.57 0. "/>
      <geometry>
        <cylinder radius="0.024" length="0.6"/>
      </geometry>
    </visual>
    <visual>
      <origin xyz="2.1 2.1 1.2" rpy="0. 1.57 0. "/>
      <geometry>
        <cylinder radius="0.024" length="0.6"/>
      </geometry>
    </visual>
    <visual>
      <origin xyz="2.1 2.1 2.2" rpy="0. 1.57 0. "/>
      <geometry>
        <cylinder radius="0.024" length="0.6"/>
      </geometry>
    </visual>
    <visual>
      <origin xyz="2.1 -2.1 0.2" rpy="0. 1.57 0. "/>
      <geometry>
        <cylinder radius="0.024" length="0.6"/>
      </geometry>
    </visual>
    <visual>
      <origin xyz="2.1 -2.1 1.2" rpy="0. 1.57 0. "/>
      <geometry>
        <cylinder radius="0.024" length="0.6"/>
      </geometry>
    </visual>
    <visual>
      <origin xyz="2.1 -2.1 2.2" rpy="0. 1.57 0. "/>
      <geometry>
        <cylinder radius="0.024" length="0.6"/>
      </geometry>
    </visual>
    <visual>
      <origin xyz="1.8 -1.6 0.2" rpy="1.57 0. 0. "/>
      <geometry>
        <cylinder radius="0.024" length="1."/>
      </geometry>
    </visual>
    <visual>
      <origin xyz="1.8 -1.6 1.2" rpy="1.57 0. 0. "/>
      <geometry>
        <cylinder radius="0.024" length="1."/>
      </geometry>
    </visual>
    <visual>
      <origin xyz="1.8 -1.6 2.2" rpy="1.57 0. 0. "/>
      <geometry>
        <cylinder radius="0.024" length="1."/>
      </geometry>
    </visual>
    <visual>
      <origin xyz="1.8 1.6 0.2" rpy="1.57 0. 0. "/>
      <geometry>
        <cylinder radius="0.024" length="1."/>
      </geometry>
    </visual>
    <visual>
      <origin xyz="1.8 1.6 1.2" rpy="1.57 0. 0. "/>
      <geometry>
        <cylinder radius="0.024" length="1."/>
      </geometry>
    </visual>
    <visual>
      <origin xyz="1.8 1.6 2.2" rpy="1.57 0. 0. "/>
      <geometry>
        <cylinder radius="0.024" length="1."/>
      </geometry>
    </visual>
    <visual>
      <origin xyz="2.4 -1.6 0.2" rpy="1.57 0. 0. "/>
      <geometry>
        <cylinder radius="0.024" length="1."/>
      </geometry>
    </visual>
    <visual>
      <origin xyz="2.4 -1.6 1.2" rpy="1.57 0. 0. "/>
      <geometry>
        <cylinder radius="0.024" length="1."/>
      </geometry>
    </visual>
    <visual>
      <origin xyz="2.4 -1.6 2.2" rpy="1.57 0. 0. "/>
      <geometry>
        <cylinder radius="0.024" length="1."/>
      </geometry>
    </visual>
    <visual>
      <origin xyz="2.4 1.6 0.2" rpy="1.57 0. 0. "/>
      <geometry>
        <cylinder radius="0.024" length="1."/>
      </geometry>
    </visual>
    <visual>
      <origin xyz="2.4 1.6 1.2" rpy="1.57 0. 0. "/>
      <geometry>
        <cylinder radius="0.024" length="1."/>
      </geometry>
    </visual>
    <visual>
      <origin xyz="2.4 1.6 2.2" rpy="1.57 0. 0. "/>
      <geometry>
        <cylinder radius="0.024" length="1."/>
      </geometry>
    </visual>
    <visual>
      <origin xyz="2.4 1.6 0.7" rpy="0.785 0. 0. "/>
      <geometry>
        <cylinder radius="0.024" length="1.414"/>
      </geometry>
    </visual>
    <visual>
      <origin xyz="2.4 1.6 1.7" rpy="0.785 0. 0. "/>
      <geometry>
        <cylinder radius="0.024" length="1.414"/>
      </geometry>
    </visual>
    <visual>
      <origin xyz="1.8 1.6 1.7" rpy="-0.785 0. 0. "/>
      <geometry>
        <cylinder radius="0.024" length="1.414"/>
      </geometry>
    </visual>
    <visual>
      <origin xyz="1.8 1.6 0.7" rpy="-0.785 0. 0. "/>
      <geometry>
        <cylinder radius="0.024" length="1.414"/>
      </geometry>
    </visual>
    <visual>
      <origin xyz="2.4 -1.6 0.7" rpy="0.785 0. 0. "/>
      <geometry>
        <cylinder radius="0.024" length="1.414"/>
      </geometry>
    </visual>
    <visual>
      <origin xyz="2.4 -1.6 1.7" rpy="0.785 0. 0. "/>
      <geometry>
        <cylinder radius="0.024" length="1.414"/>
      </geometry>
    </visual>
    <visual>
      <origin xyz="1.8 -1.6 1.7" rpy="-0.785 0. 0. "/>
      <geometry>
        <cylinder radius="0.024" length="1.414"/>
      </geometry>
    </visual>
    <visual>
      <origin xyz="1.8 -1.6 0.7" rpy="-0.785 0. 0. "/>
      <geometry>
        <cylinder radius="0.024" length="1.414"/>
      </geometry>
    </visual>
  </link>
  <link name="scene_kuka_arm_link_1_kuka_arm_link_1">
    <visual>
      <origin xyz="0. 0. 0." rpy="1.570788 1.5707964 0. "/>
      <geometry>
        <mesh filename="meshes/scene_kuka_arm_link_1_kuka_arm_link_1_visuals_mesh.obj" scale="1. 1. 1."/>
      </geometry>
    </visual>
    <visual>
      <origin xyz="0. 0. 0." rpy="1.570788 1.5707964 0. "/>
      <geometry>
        <mesh filename="meshes/scene_kuka_arm_link_1_kuka_arm_link_1_collisions_mesh.obj" scale="1. 1. 1."/>
      </geometry>
    </visual>
  </link>
</robot>
