<?xml version="1.0" encoding="UTF-8"?>

<robot name="robot">
    <link name="robot">
        <visual>
            <origin xyz="0. 0. 0." rpy="-0.0000091 0. 0. "/>
            <geometry>
                <mesh filename="meshes/worldBody___visuals___mesh.obj" scale="1. 1. 1."/>
            </geometry>
        </visual>
        <collision>
            <origin xyz="0. 0. 0." rpy="-0.0000091 0. 0. "/>
            <geometry>
                <mesh filename="meshes/worldBody___collisions___mesh.obj" scale="1. 1. 1."/>
            </geometry>
        </collision>
    </link>
    <link name="robot_kuka_arm_link_1_kuka_arm_link_1">
        <visual>
            <origin xyz="0. 0. 0." rpy="1.570788 1.5707964 0. "/>
            <geometry>
                <mesh filename="meshes/robot_kuka_arm_link_1_kuka_arm_link_1_visuals_mesh.obj" scale="1. 1. 1."/>
            </geometry>
        </visual>
        <visual>
            <origin xyz="0. 0. 0." rpy="1.570788 1.5707964 0. "/>
            <geometry>
                <mesh filename="meshes/robot_kuka_arm_link_1_kuka_arm_link_1_collisions_mesh.obj" scale="1. 1. 1."/>
            </geometry>
        </visual>
    </link>
    <link name="kuka_arm_link_2">
        <visual>
            <origin xyz="0. 0. 0." rpy="-0.0000091 0. -1.5707964"/>
            <geometry>
                <mesh filename="meshes/kuka_arm_link_2_visuals_mesh.obj" scale="1. 1. 1."/>
            </geometry>
        </visual>
        <collision>
            <origin xyz="0. 0. 0." rpy="-0.0000091 0. -1.5707964"/>
            <geometry>
                <mesh filename="meshes/kuka_arm_link_2_collisions_mesh.obj" scale="1. 1. 1."/>
            </geometry>
        </collision>
    </link>
    <link name="kuka_arm_link_3">
        <visual>
            <origin xyz="-0.184 0. 0. " rpy="-0.0000091 0. -1.5707964"/>
            <geometry>
                <mesh filename="meshes/kuka_arm_link_3_visuals_mesh.obj" scale="1. 1. 1."/>
            </geometry>
        </visual>
        <collision>
            <origin xyz="-0.184 0. 0. " rpy="-0.0000091 0. -1.5707964"/>
            <geometry>
                <mesh filename="meshes/kuka_arm_link_3_collisions_mesh.obj" scale="1. 1. 1."/>
            </geometry>
        </collision>
    </link>
    <link name="kuka_arm_link_4">
        <visual>
            <origin xyz="0. 0. 0." rpy="-0.0000091 0. 0. "/>
            <geometry>
                <mesh filename="meshes/kuka_arm_link_4_visuals_mesh.obj" scale="1. 1. 1."/>
            </geometry>
        </visual>
        <collision>
            <origin xyz="0. 0. 0." rpy="-0.0000091 0. 0. "/>
            <geometry>
                <mesh filename="meshes/kuka_arm_link_4_collisions_mesh.obj" scale="1. 1. 1."/>
            </geometry>
        </collision>
    </link>
    <link name="kuka_arm_link_5">
        <visual>
            <origin xyz="0. 0.0000001 0. " rpy="-0.0000091 0. -1.5707964"/>
            <geometry>
                <mesh filename="meshes/kuka_arm_link_5_visuals_mesh.obj" scale="1. 1. 1."/>
            </geometry>
        </visual>
        <collision>
            <origin xyz="0. 0.0000001 0. " rpy="-0.0000091 0. -1.5707964"/>
            <geometry>
                <mesh filename="meshes/kuka_arm_link_5_collisions_mesh.obj" scale="1. 1. 1."/>
            </geometry>
        </collision>
    </link>
    <link name="kuka_arm_link_6">
        <visual>
            <origin xyz="0.0000001 0. 0. " rpy="1.570788 0. 0. "/>
            <geometry>
                <mesh filename="meshes/kuka_arm_link_6_visuals_mesh.obj" scale="1. 1. 1."/>
            </geometry>
        </visual>
        <collision>
            <origin xyz="0.0000001 0. 0. " rpy="1.570788 0. 0. "/>
            <geometry>
                <mesh filename="meshes/kuka_arm_link_6_collisions_mesh.obj" scale="1. 1. 1."/>
            </geometry>
        </collision>
    </link>
    <link name="gripper_tcp">
        <visual>
            <origin xyz="0.15 0 -0.05" rpy="0 0 0"/>
            <geometry>
                <sphere radius="0.01"/>
            </geometry>
            <material name="red">
                <color rgba="1 0 0 1"/>
            </material>
        </visual>
    </link>
    <link name="gripper_link">
        <inertial>
            <origin rpy="0 0 0" xyz="0 0 0"/>
            <mass value="0.3"/>
            <inertia ixx="0.0001" ixy="0" ixz="0" iyy="0.0002" iyz="0" izz="0.0001"/>
        </inertial>
        <visual>
            <origin rpy="0 0 0" xyz="0 0 0"/>
            <geometry>
                <mesh filename="meshes/kuka_arm_link_6_visuals_gripper_base_mesh.obj"/>
            </geometry>
        </visual>
        <collision>
            <origin rpy="0 0 0" xyz="0 0 0"/>
            <geometry>
                <mesh filename="meshes/kuka_arm_link_6_visuals_gripper_base_mesh.obj"/>
            </geometry>
        </collision>
    </link>
    <link name="left_gripper_finger_link">
        <visual>
            <origin xyz="0. 0. 0." rpy="-1.5708046 0. -1.5707964"/>
            <geometry>
                <mesh filename="meshes/left_gripper_finger_link_visuals_mesh.obj" scale="1. 1. 1."/>
            </geometry>
        </visual>
        <collision>
            <origin xyz="0. 0. 0." rpy="-1.5708046 0. -1.5707964"/>
            <geometry>
                <mesh filename="meshes/left_gripper_finger_link_collisions_mesh.obj" scale="1. 1. 1."/>
            </geometry>
        </collision>
    </link>
    <link name="right_gripper_finger_link">
        <visual>
            <origin xyz="0. 0. 0." rpy="1.570788 0. -1.5707964"/>
            <geometry>
                <mesh filename="meshes/right_gripper_finger_link_visuals_mesh.obj" scale="1. 1. 1."/>
            </geometry>
        </visual>
        <collision>
            <origin xyz="0. 0. 0." rpy="1.570788 0. -1.5707964"/>
            <geometry>
                <mesh filename="meshes/right_gripper_finger_link_collisions_mesh.obj" scale="1. 1. 1."/>
            </geometry>
        </collision>
    </link>

    <joint name="joint_1" type="revolute">
        <origin xyz="0. 0. 0.33" rpy="0. -1.5707964 0. "/>
        <parent link="robot"/>
        <child link="robot_kuka_arm_link_1_kuka_arm_link_1"/>
        <axis xyz="1. 0. 0."/>
        <limit lower="-3.2288596" upper="3.2288596" effort="0." velocity="17453.2925199"/>
    </joint>
    <joint name="joint_2" type="revolute">
        <origin xyz="0.42 0. -0.35" rpy="1.5707964 0. 1.5707964"/>
        <parent link="robot_kuka_arm_link_1_kuka_arm_link_1"/>
        <child link="kuka_arm_link_2"/>
        <axis xyz="1. 0. 0."/>
        <limit lower="-0.785398" upper="1.48353" effort="0." velocity="17453.2925199"/>
    </joint>
    <joint name="joint_3" type="revolute">
        <origin xyz="0. 0. 1.25" rpy="0. 0. 0."/>
        <parent link="kuka_arm_link_2"/>
        <child link="kuka_arm_link_3"/>
        <axis xyz="1. 0. 0."/>
        <limit lower="-3.6651898" upper="1.1344599" effort="0." velocity="17453.2925199"/>
    </joint>
    <joint name="joint_4" type="revolute">
        <origin xyz="0. -0.9599999 -0.054 " rpy="0. 0. -1.5707964"/>
        <parent link="kuka_arm_link_3"/>
        <child link="kuka_arm_link_4"/>
        <axis xyz="1. 0. 0."/>
        <limit lower="-6.1086497" upper="6.1086497" effort="0." velocity="17453.2925199"/>
    </joint>
    <joint name="joint_5" type="revolute">
        <origin xyz="0.54 0. 0. " rpy="0. 0. 1.5707964"/>
        <parent link="kuka_arm_link_4"/>
        <child link="kuka_arm_link_5"/>
        <axis xyz="1. 0. 0."/>
        <limit lower="-2.1816598" upper="2.1816598" effort="0." velocity="17453.2925199"/>
    </joint>
    <joint name="joint_6" type="revolute">
        <origin xyz="0. -0.1930001 0. " rpy="0. 0. -1.5707964"/>
        <parent link="kuka_arm_link_5"/>
        <child link="kuka_arm_link_6"/>
        <axis xyz="1. 0. 0."/>
        <limit lower="-6.1086497" upper="6.1086497" effort="0." velocity="17453.2925199"/>
    </joint>

    <joint name="left_gripper_finger_joint" type="prismatic">
        <origin xyz="0.26 0.0725 0. " rpy="3.1415927 0. -1.5707964"/>
        <parent link="kuka_arm_link_6"/>
        <child link="left_gripper_finger_link"/>
        <axis xyz="1. 0. 0."/>
        <limit lower="-0.01" upper="0.06" effort="0." velocity="1000000."/>
    </joint>
    <joint name="right_gripper_finger_joint" type="prismatic">
        <origin xyz="0.26 -0.0725 0. " rpy="0. 0. 1.5707964"/>
        <parent link="kuka_arm_link_6"/>
        <child link="right_gripper_finger_link"/>
        <axis xyz="1. 0. 0."/>
        <limit lower="-0.01" upper="0.06" effort="0." velocity="1000000."/>
    </joint>
    <joint name="gripper_tcp_joint" type="fixed">
        <origin rpy="0 0 0" xyz="0 0 0.05"/>
        <parent link="gripper_link"/>
        <child link="gripper_tcp"/>
    </joint>

    <joint name="gripper_joint" type="fixed">
        <parent link="kuka_arm_link_6"/>
        <child link="gripper_link"/>
        <origin rpy="1.57 0 0" xyz="0.11 0 0"/>
        <axis xyz="0 1 0"/>
    </joint>
</robot>
